  File "tbot.py", line 68
    fio = sheet.cell(row = i - 1, column = 1).value
                                                  ^
TabError: inconsistent use of tabs and spaces in indentation
  File "tbot.py", line 68
    fio = sheet.cell(row = i - 1, column = 1).value
                                                  ^
TabError: inconsistent use of tabs and spaces in indentation
  File "tbot.py", line 71
    return sheet.cell(row = i - 1, column = 1).value
                                                   ^
TabError: inconsistent use of tabs and spaces in indentation
  File "tbot.py", line 71
    return sheet.cell(row = i - 1, column = 1).value
                                                   ^
TabError: inconsistent use of tabs and spaces in indentation
  File "tbot.py", line 71
    return sheet.cell(row = i - 1, column = 1).value
                                                   ^
TabError: inconsistent use of tabs and spaces in indentation
  File "tbot.py", line 71
    return sheet.cell(row = i - 1, column = 1).value
                                                   ^
TabError: inconsistent use of tabs and spaces in indentation
  File "tbot.py", line 68
    return sheet.cell(row = i - 1, column = 1).value
                                                   ^
TabError: inconsistent use of tabs and spaces in indentation
2022-04-12 00:03:25,955 (__init__.py:688 MainThread) ERROR - TeleBot: "A request to the Telegram API was unsuccessful. Error code: 409. Description: Conflict: terminated by other getUpdates request; make sure that only one bot instance is running"
2022-04-16 18:16:16,157 (__init__.py:688 MainThread) ERROR - TeleBot: "A request to the Telegram API was unsuccessful. Error code: 502. Description: Bad Gateway"
2022-04-16 18:16:16,531 (__init__.py:688 MainThread) ERROR - TeleBot: "A request to the Telegram API was unsuccessful. Error code: 502. Description: Bad Gateway"
2022-04-18 03:39:19,435 (__init__.py:688 MainThread) ERROR - TeleBot: "A request to the Telegram API was unsuccessful. Error code: 502. Description: Bad Gateway"
2022-04-18 03:39:19,819 (__init__.py:688 MainThread) ERROR - TeleBot: "A request to the Telegram API was unsuccessful. Error code: 502. Description: Bad Gateway"
2022-04-25 12:41:42,932 (__init__.py:688 MainThread) ERROR - TeleBot: "A request to the Telegram API was unsuccessful. Error code: 409. Description: Conflict: terminated by other getUpdates request; make sure that only one bot instance is running"
2022-05-05 04:08:19,469 (__init__.py:688 MainThread) ERROR - TeleBot: "A request to the Telegram API was unsuccessful. Error code: 502. Description: Bad Gateway"
2022-05-05 04:08:19,839 (__init__.py:688 MainThread) ERROR - TeleBot: "A request to the Telegram API was unsuccessful. Error code: 502. Description: Bad Gateway"
HTTPSConnectionPool(host='api.telegram.org', port=443): Read timed out. (read timeout=25)
HTTPSConnectionPool(host='api.telegram.org', port=443): Read timed out. (read timeout=25)
HTTPSConnectionPool(host='api.telegram.org', port=443): Max retries exceeded with url: /bot5125341770:AAF11nLzMCoeFV-gf96iL19hDyhOfidqo7g/getUpdates?offset=927125914&timeout=20 (Caused by NewConnectionError('<urllib3.connection.VerifiedHTTPSConnection object at 0x7f1a8d2a7fd0>: Failed to establish a new connection: [Errno -2] Name or service not known',))
HTTPSConnectionPool(host='api.telegram.org', port=443): Max retries exceeded with url: /bot5125341770:AAF11nLzMCoeFV-gf96iL19hDyhOfidqo7g/getUpdates?offset=927125914&timeout=20 (Caused by NewConnectionError('<urllib3.connection.VerifiedHTTPSConnection object at 0x7f1a8cd15b70>: Failed to establish a new connection: [Errno -2] Name or service not known',))
HTTPSConnectionPool(host='api.telegram.org', port=443): Max retries exceeded with url: /bot5125341770:AAF11nLzMCoeFV-gf96iL19hDyhOfidqo7g/getUpdates?offset=927125914&timeout=20 (Caused by NewConnectionError('<urllib3.connection.VerifiedHTTPSConnection object at 0x7f1a8cf2bc50>: Failed to establish a new connection: [Errno -2] Name or service not known',))
HTTPSConnectionPool(host='api.telegram.org', port=443): Max retries exceeded with url: /bot5125341770:AAF11nLzMCoeFV-gf96iL19hDyhOfidqo7g/getUpdates?offset=927125914&timeout=20 (Caused by NewConnectionError('<urllib3.connection.VerifiedHTTPSConnection object at 0x7f1a8cbe47b8>: Failed to establish a new connection: [Errno -2] Name or service not known',))
HTTPSConnectionPool(host='api.telegram.org', port=443): Max retries exceeded with url: /bot5125341770:AAF11nLzMCoeFV-gf96iL19hDyhOfidqo7g/getUpdates?offset=927125914&timeout=20 (Caused by NewConnectionError('<urllib3.connection.VerifiedHTTPSConnection object at 0x7f1a8cc23b00>: Failed to establish a new connection: [Errno -2] Name or service not known',))
HTTPSConnectionPool(host='api.telegram.org', port=443): Max retries exceeded with url: /bot5125341770:AAF11nLzMCoeFV-gf96iL19hDyhOfidqo7g/getUpdates?offset=927125914&timeout=20 (Caused by NewConnectionError('<urllib3.connection.VerifiedHTTPSConnection object at 0x7f1a8d2a70f0>: Failed to establish a new connection: [Errno -2] Name or service not known',))
HTTPSConnectionPool(host='api.telegram.org', port=443): Max retries exceeded with url: /bot5125341770:AAF11nLzMCoeFV-gf96iL19hDyhOfidqo7g/getUpdates?offset=927125914&timeout=20 (Caused by NewConnectionError('<urllib3.connection.VerifiedHTTPSConnection object at 0x7f1a8ca11390>: Failed to establish a new connection: [Errno -2] Name or service not known',))
HTTPSConnectionPool(host='api.telegram.org', port=443): Max retries exceeded with url: /bot5125341770:AAF11nLzMCoeFV-gf96iL19hDyhOfidqo7g/getUpdates?offset=927125914&timeout=20 (Caused by NewConnectionError('<urllib3.connection.VerifiedHTTPSConnection object at 0x7f1a8cc68b38>: Failed to establish a new connection: [Errno -2] Name or service not known',))
HTTPSConnectionPool(host='api.telegram.org', port=443): Max retries exceeded with url: /bot5125341770:AAF11nLzMCoeFV-gf96iL19hDyhOfidqo7g/getUpdates?offset=927125914&timeout=20 (Caused by NewConnectionError('<urllib3.connection.VerifiedHTTPSConnection object at 0x7f1a8cd0cdd8>: Failed to establish a new connection: [Errno -2] Name or service not known',))
HTTPSConnectionPool(host='api.telegram.org', port=443): Max retries exceeded with url: /bot5125341770:AAF11nLzMCoeFV-gf96iL19hDyhOfidqo7g/getUpdates?offset=927125914&timeout=20 (Caused by NewConnectionError('<urllib3.connection.VerifiedHTTPSConnection object at 0x7f1a8cf2bdd8>: Failed to establish a new connection: [Errno -2] Name or service not known',))
HTTPSConnectionPool(host='api.telegram.org', port=443): Read timed out. (read timeout=25)
HTTPSConnectionPool(host='api.telegram.org', port=443): Max retries exceeded with url: /bot5125341770:AAF11nLzMCoeFV-gf96iL19hDyhOfidqo7g/getUpdates?offset=927125914&timeout=20 (Caused by NewConnectionError('<urllib3.connection.VerifiedHTTPSConnection object at 0x7f1a8cdcb240>: Failed to establish a new connection: [Errno 101] Network is unreachable',))
HTTPSConnectionPool(host='api.telegram.org', port=443): Max retries exceeded with url: /bot5125341770:AAF11nLzMCoeFV-gf96iL19hDyhOfidqo7g/getUpdates?offset=927125914&timeout=20 (Caused by NewConnectionError('<urllib3.connection.VerifiedHTTPSConnection object at 0x7f1a8d2a7a58>: Failed to establish a new connection: [Errno 101] Network is unreachable',))
HTTPSConnectionPool(host='api.telegram.org', port=443): Max retries exceeded with url: /bot5125341770:AAF11nLzMCoeFV-gf96iL19hDyhOfidqo7g/getUpdates?offset=927125914&timeout=20 (Caused by NewConnectionError('<urllib3.connection.VerifiedHTTPSConnection object at 0x7f1a8ca118d0>: Failed to establish a new connection: [Errno 101] Network is unreachable',))
HTTPSConnectionPool(host='api.telegram.org', port=443): Max retries exceeded with url: /bot5125341770:AAF11nLzMCoeFV-gf96iL19hDyhOfidqo7g/getUpdates?offset=927125914&timeout=20 (Caused by NewConnectionError('<urllib3.connection.VerifiedHTTPSConnection object at 0x7f1a8ce102b0>: Failed to establish a new connection: [Errno 101] Network is unreachable',))
HTTPSConnectionPool(host='api.telegram.org', port=443): Max retries exceeded with url: /bot5125341770:AAF11nLzMCoeFV-gf96iL19hDyhOfidqo7g/getUpdates?offset=927125914&timeout=20 (Caused by NewConnectionError('<urllib3.connection.VerifiedHTTPSConnection object at 0x7f1a8cf2bbe0>: Failed to establish a new connection: [Errno 101] Network is unreachable',))
HTTPSConnectionPool(host='api.telegram.org', port=443): Max retries exceeded with url: /bot5125341770:AAF11nLzMCoeFV-gf96iL19hDyhOfidqo7g/getUpdates?offset=927125914&timeout=20 (Caused by NewConnectionError('<urllib3.connection.VerifiedHTTPSConnection object at 0x7f1a8cc68d30>: Failed to establish a new connection: [Errno 101] Network is unreachable',))
HTTPSConnectionPool(host='api.telegram.org', port=443): Max retries exceeded with url: /bot5125341770:AAF11nLzMCoeFV-gf96iL19hDyhOfidqo7g/getUpdates?offset=927125914&timeout=20 (Caused by NewConnectionError('<urllib3.connection.VerifiedHTTPSConnection object at 0x7f1a8c7e6940>: Failed to establish a new connection: [Errno 101] Network is unreachable',))
HTTPSConnectionPool(host='api.telegram.org', port=443): Max retries exceeded with url: /bot5125341770:AAF11nLzMCoeFV-gf96iL19hDyhOfidqo7g/getUpdates?offset=927125914&timeout=20 (Caused by NewConnectionError('<urllib3.connection.VerifiedHTTPSConnection object at 0x7f1a8c7e61d0>: Failed to establish a new connection: [Errno 101] Network is unreachable',))
HTTPSConnectionPool(host='api.telegram.org', port=443): Max retries exceeded with url: /bot5125341770:AAF11nLzMCoeFV-gf96iL19hDyhOfidqo7g/getUpdates?offset=927125914&timeout=20 (Caused by NewConnectionError('<urllib3.connection.VerifiedHTTPSConnection object at 0x7f1a8cc68128>: Failed to establish a new connection: [Errno 101] Network is unreachable',))
HTTPSConnectionPool(host='api.telegram.org', port=443): Max retries exceeded with url: /bot5125341770:AAF11nLzMCoeFV-gf96iL19hDyhOfidqo7g/getUpdates?offset=927125914&timeout=20 (Caused by NewConnectionError('<urllib3.connection.VerifiedHTTPSConnection object at 0x7f1a8cf2bd68>: Failed to establish a new connection: [Errno 101] Network is unreachable',))
HTTPSConnectionPool(host='api.telegram.org', port=443): Max retries exceeded with url: /bot5125341770:AAF11nLzMCoeFV-gf96iL19hDyhOfidqo7g/getUpdates?offset=927125914&timeout=20 (Caused by NewConnectionError('<urllib3.connection.VerifiedHTTPSConnection object at 0x7f1a8c861860>: Failed to establish a new connection: [Errno 101] Network is unreachable',))
HTTPSConnectionPool(host='api.telegram.org', port=443): Max retries exceeded with url: /bot5125341770:AAF11nLzMCoeFV-gf96iL19hDyhOfidqo7g/getUpdates?offset=927125914&timeout=20 (Caused by NewConnectionError('<urllib3.connection.VerifiedHTTPSConnection object at 0x7f1a8cf2bd68>: Failed to establish a new connection: [Errno 101] Network is unreachable',))
HTTPSConnectionPool(host='api.telegram.org', port=443): Max retries exceeded with url: /bot5125341770:AAF11nLzMCoeFV-gf96iL19hDyhOfidqo7g/getUpdates?offset=927125914&timeout=20 (Caused by NewConnectionError('<urllib3.connection.VerifiedHTTPSConnection object at 0x7f1a8cc68e48>: Failed to establish a new connection: [Errno 101] Network is unreachable',))